<mujoco model="ur3e_robot">
    <compiler angle="radian" />
    <size njmax="500" nconmax="100" />
    <asset>
        <mesh name="ur3_base" file="ur3e/base.stl" />
        <mesh name="ur3_shoulder" file="ur3e/shoulder.stl" />
        <mesh name="ur3_upperarm" file="ur3e/upperarm.stl" />
        <mesh name="ur3_forearm" file="ur3e/forearm.stl" />
        <mesh name="ur3_wrist1" file="ur3e/wrist1.stl" />
        <mesh name="ur3_wrist2" file="ur3e/wrist2.stl" />
        <mesh name="ur3_wrist3" file="ur3e/wrist3.stl" />
        <mesh name="ur16_base" file="ur16e/base.stl" />
        <mesh name="ur16_shoulder" file="ur16e/shoulder.stl" />
        <mesh name="ur16_upperarm" file="ur16e/upperarm.stl" />
        <mesh name="ur16_forearm" file="ur16e/forearm.stl" />
        <mesh name="ur16_wrist1" file="ur16e/wrist1.stl" />
        <mesh name="ur16_wrist2" file="ur16e/wrist2.stl" />
        <mesh name="ur16_wrist3" file="ur16e/wrist3.stl" />
        <mesh name="oct_nozzle" file="meshes/nozzle_convex_primitive.STL"/>
    </asset>
    <option 
        timestep="0.005" integrator="RK4">
    </option>
	<actuator>
		<motor gear="1.0" joint="ur3_shoulder_pan_joint" name="ur3_shoulder_pan_joint" ctrllimited="true" ctrlrange="-100 100"/>
		<motor gear="1.0" joint="ur3_shoulder_lift_joint" name="ur3_shoulder_lift_joint" ctrllimited="true" ctrlrange="-100 100"/>
		<motor gear="1.0" joint="ur3_elbow_joint" name="ur3_elbow_joint" ctrllimited="true" ctrlrange="-100 100"/>
		<motor gear="1.0" joint="ur3_wrist_1_joint" name="ur3_wrist_1_joint" ctrllimited="true" ctrlrange="-100 100"/>
        <motor gear="1.0" joint="ur3_wrist_2_joint" name="ur3_wrist_2_joint" ctrllimited="true" ctrlrange="-100 100"/>
        <motor gear="1.0" joint="ur3_wrist_3_joint" name="ur3_wrist_3_joint" ctrllimited="true" ctrlrange="-100 100"/>
		<motor gear="1.0" joint="ur16_shoulder_pan_joint" name="ur16_shoulder_pan_joint" ctrllimited="true" ctrlrange="-100 100"/>
		<motor gear="1.0" joint="ur16_shoulder_lift_joint" name="ur16_shoulder_lift_joint" ctrllimited="true" ctrlrange="-100 100"/>
		<motor gear="1.0" joint="ur16_elbow_joint" name="ur16_elbow_joint" ctrllimited="true" ctrlrange="-100 100"/>
		<motor gear="1.0" joint="ur16_wrist_1_joint" name="ur16_wrist_1_joint" ctrllimited="true" ctrlrange="-100 100"/>
        <motor gear="1.0" joint="ur16_wrist_2_joint" name="ur16_wrist_2_joint" ctrllimited="true" ctrlrange="-100 100"/>
        <motor gear="1.0" joint="ur16_wrist_3_joint" name="ur16_wrist_3_joint" ctrllimited="true" ctrlrange="-100 100"/>
        <!-- <motor gear="1.0" joint="joint:2" name="bact"/> -->
	</actuator>    
    <sensor>
        <force name='force_sensor' site='force_sensor'/>
        <torque name='torque_sensor' site='torque_sensor'/>
        <accelerometer name='acc' site='acc'/>
        <!-- <gyro name='gyro' site='gyro'/> -->
    </sensor>
    <worldbody>
    <!-- <camera name="bodyhigh2" pos="0 0 1.5" quat="0 0 0.382683 0 0.923876"/> -->
    <!-- <camera name="bodyhigh2" pos="0 0 1.5" quat="0 0.923876 0 0.382683"/> -->
        <geom quat="-1 0 0 0" type="mesh" rgba="0.7 0.7 0.7 1" mesh="ur3_base" name="ur3_base"/>
        <body name="ur3_shoulder_link" pos="0 0 0.15285" quat="1 0 0 0">
            <inertial pos="0 0 0" mass="2" diaginertia="0.00809316 0.00809316 0.005625" />
            <joint name="ur3_shoulder_pan_joint" pos="0 0 0" axis="0 0 1" limited="true" range="-6.28319 6.28319" />
            <geom quat="0 0 0 1" type="mesh" rgba="0.7 0.7 0.7 1" mesh="ur3_shoulder" name="ur3_shoulder"/>
            <body name="ur3_upper_arm_link" pos="0 0 0" quat="0.707107 0.707107 0 0">
                <inertial pos="-0.121825 0 0.12" quat="0.707107 0 0.707107 0" mass="3.42" diaginertia="0.0217285 0.0217285 0.00961875" />
                <joint name="ur3_shoulder_lift_joint" pos="0 0 0" axis="0 0 1" limited="true" range="-6.28319 6.28319" />
                <!-- <joint name="shoulder_lift_joint" pos="0 0 0" axis="0 0 1" limited="true" range="-1.4544168120244623 -1.40" /> -->
                <geom pos="0 0 0.12" quat="0.5 0.5 -0.5 -0.5" type="mesh" rgba="0.7 0.7 0.7 1" mesh="ur3_upperarm" name="ur3_upperarm" />
                <body name="ur3_forearm_link" pos="-0.24355 0 0">
                    <inertial pos="-0.1066 0 0.027" quat="0.707107 0 0.707107 0" mass="1.26" diaginertia="0.00654457 0.00654457 0.00354375" />
                    <joint name="ur3_elbow_joint" pos="0 0 0" axis="0 0 1" limited="true" range="-3.14159 3.14159" />
                    <!-- <joint name="elbow_joint" pos="0 0 0" axis="0 0 1" limited="true" range="-1.7540615253663132 -1.70" /> -->
                    <geom pos="0 0 0.027" quat="0.5 0.5 -0.5 -0.5" type="mesh" rgba="0.7 0.7 0.7 1" mesh="ur3_forearm" name="ur3_forearm" />
                    <body name="ur3_wrist_1_link" pos="-0.2132 0 0.13105">
                        <inertial pos="0 0 0" quat="0.5 0.5 -0.5 0.5" mass="0.8" diaginertia="0.00225 0.002085 0.002085" />
                        <joint name="ur3_wrist_1_joint" pos="0 0 0" axis="0 0 1" limited="true" range="-6.28319 6.28319" />
                        <!-- <joint name="wrist_1_joint" pos="0 0 0" axis="0 0 1" limited="true" range="-3.067826543422323 -2.9" /> -->
                        <geom pos="0 0 -0.104" quat="0.707107 0.707107 0 0" type="mesh" rgba="0.7 0.7 0.7 1" mesh="ur3_wrist1" name="ur3_wrist1" />
                        <body name="ur3_wrist_2_link" pos="0 -0.08535 -1.75056e-11" quat="0.707107 0.707107 0 0">
                            <inertial pos="0 0 0" quat="0.5 0.5 -0.5 0.5" mass="0.8" diaginertia="0.00225 0.002085 0.002085" />
                            <joint name="ur3_wrist_2_joint" pos="0 0 0" axis="0 0 1" limited="true" range="-6.28319 6.28319" />
                            <!-- <joint name="wrist_2_joint" pos="0 0 0" axis="0 0 1" limited="true" range="0.10 0.11940037001951656" />  -->
                            <geom pos="0 0 -0.08535" type="mesh" rgba="0.7 0.7 0.7 1" mesh="ur3_wrist2" name="ur3_wrist2"/>
                            <body name="ur3_wrist_3_link" pos="0 0.0921 -1.889e-11" quat="0.707107 -0.707107 0 0">
                                <inertial pos="0 0 -0.02" quat="0.5 0.5 -0.5 0.5" mass="0.35" diaginertia="0.0001792 0.000136267 0.000136267" />
                                <!-- <joint name="wrist_3_joint" pos="0 0 0" axis="0 0 1" limited="true" range="-1.588058798181077 -1.57" /> -->
                                <joint name="ur3_wrist_3_joint" pos="0 0 0" axis="0 0 1" limited="true" range="-6.28319 6.28319" />
                                <geom pos="0 0 -0.0921" quat="0.707107 0.707107 0 0" type="mesh" rgba="0.7 0.7 0.7 1" mesh="ur3_wrist3" name="ur3_wrist3" />
                                <body name="peg_base" pos="0 0 0.0025" >
                                    <geom pos="0.0 0 0.0"  size="0.03 0.0025" type="cylinder" rgba="0.7 0.7 0.7 1" name="pegbase" />
                                    <site name='force_sensor' pos="0 0 0.00" size='0.01 0.01 0.01' rgba='0 1 0 0' type='sphere' group='1'/>
                                    <site name='torque_sensor' pos="0 0 0.00" size='0.01 0.01 0.01' rgba='0 1 0 0' type='sphere' group='1'/>  
                                    <site name='acc' pos="0 0 0.0" size='0.01 0.01 0.01' rgba='0 1 0 0' type='sphere' group='1'/>                                  
                                    <body name="nozzle" pos="0 0 0.0" >
                                        <body name="nozzle0" pos="0 0 0.00">
                                            <geom type="mesh" contype="1" conaffinity="1" group="1" rgba="1 0 0 1" mesh="oct_nozzle" name="nozzle0"/>
                                        </body>

                                        <body name="nozzle45" pos="0 0 0.00" quat="0.9238795 0 0 0.3826834">
                                            <geom type="mesh" contype="1" conaffinity="1" group="1" rgba="1 0 0 1" mesh="oct_nozzle" name="nozzle45"/>
                                        </body>

                                        <body name="nozzle90" pos="0 0 0.00" quat="0.7071068 0 0 0.7071068">
                                            <geom type="mesh" contype="1" conaffinity="1" group="1" rgba="1 0 0 1" mesh="oct_nozzle" name="nozzle90"/>
                                        </body>

                                        <body name="nozzle135" pos="0 0 0.00" quat="0.3826834 0 0 0.9238795">
                                            <geom type="mesh" contype="1" conaffinity="1" group="1" rgba="1 0 0 1" mesh="oct_nozzle" name="nozzle135"/>
                                        </body>

                                        <body name="nozzle180" pos="0 0 0.0" quat="0 0 0 1">
                                            <geom type="mesh" contype="1" conaffinity="1" group="1" rgba="1 0 0 1" mesh="oct_nozzle" name="nozzle180"/>
                                        </body>

                                        <body name="nozzle225" pos="0 0 0.00" quat="-0.3826834 0 0 0.9238795">
                                            <geom type="mesh" contype="1" conaffinity="1" group="1" rgba="1 0 0 1" mesh="oct_nozzle" name="nozzle225"/>
                                        </body>

                                        <body name="nozzle270" pos="0 0 0.00" quat="-0.7071068 0 0 0.7071068">
                                            <geom type="mesh" contype="1" conaffinity="1" group="1" rgba="1 0 0 1" mesh="oct_nozzle" name="nozzle270"/>
                                        </body>

                                        <body name="nozzle315" pos="0 0 0.00" quat="-0.9238795 0 0 0.3826834">
                                            <geom type="mesh" contype="1" conaffinity="1" group="1" rgba="1 0 0 1" mesh="oct_nozzle" name="nozzle315"/>
                                        </body>
                                        <site name='ur3:ee' pos="0 0.0 0.0" size='0.01 0.01 0.01' rgba='0 1 1 1' type='sphere' group='1'/>
                                    </body>
                                </body> 
                             
                            </body>
                        </body>
                    </body>
                </body>
            </body>
        </body>
        <site name='wpt1' pos="0.20 0.2 0.4" quat="0.707107 0 0.707107 0" size='0.01 0.01 0.01' rgba='0 1 1 1' type='sphere' group='1'/>
        <site name='wpt2' pos="0.32 0.2 0.4" quat="0.707107 0 -0.707107 0" size='0.01 0.01 0.01' rgba='0 0 1 1' type='sphere' group='1'/>
        <geom pos="0.8 0 0" quat="-1 0 0 0" type="mesh" rgba="0.7 0.7 0.7 1" mesh="ur16_base" name="ur16_base"/>
        <body name="ur16_shoulder_link" pos="0.8 0 0.1909" quat="0 0 0 1">
            <inertial pos="0 0 0" mass="7.369" diaginertia="0.0298193 0.0298193 0.0207253" />
            <joint name="ur16_shoulder_pan_joint" pos="0 0 0" axis="0 0 1" limited="true" range="-6.28319 6.28319" />
            <geom quat="0 0 0 1" type="mesh" rgba="0.7 0.7 0.7 1" mesh="ur16_shoulder" name="ur16_shoulder"/>
            <body name="ur16_upper_arm_link" pos="0 0 0" quat="0.707107 0.707107 0 0">
                <inertial pos="-0.2392 0 0.175" quat="0.707107 0 0.707107 0" mass="10.45" diaginertia="0.214 0.214 0.0293906" />
                <joint name="ur16_shoulder_lift_joint" pos="0 0 0" axis="0 0 1" limited="true" range="-6.28319 6.28319" />
                <geom pos="0 0 0.176" quat="0.5 0.5 -0.5 -0.5" type="mesh" rgba="0.7 0.7 0.7 1" mesh="ur16_upperarm" name="ur16_upperarm"/>
                <body name="ur16_forearm_link" pos="-0.4784 0 0">
                    <inertial pos="-0.18 0 0.04" quat="0.707107 0 0.707107 0" mass="4.321" diaginertia="0.0527432 0.0527432 0.0121528" />
                    <joint name="ur16_elbow_joint" pos="0 0 0" axis="0 0 1" limited="true" range="-3.14159 3.14159" />
                    <geom pos="0 0 0.04" quat="0.5 0.5 -0.5 -0.5" type="mesh" rgba="0.7 0.7 0.7 1" mesh="ur16_forearm" name="ur16_forearm" />
                    <body name="ur16_wrist_1_link" pos="-0.36 0 0.17415">
                        <inertial pos="0 0 0" quat="0.5 0.5 -0.5 0.5" mass="2.18" diaginertia="0.00613125 0.00568162 0.00568162" />
                        <joint name="ur16_wrist_1_joint" pos="0 0 0" axis="0 0 1" limited="true" range="-6.28319 6.28319" />
                        <geom pos="0 0 -0.135" quat="0.707107 0.707107 0 0" type="mesh" rgba="0.7 0.7 0.7 1" mesh="ur16_wrist1" name="ur16_wrist1"/>
                        <body name="ur16_wrist_2_link" pos="0 -0.11985 -2.45816e-11" quat="0.707107 0.707107 0 0">
                            <inertial pos="0 0 0" quat="0.5 0.5 -0.5 0.5" mass="2.033" diaginertia="0.00571781 0.0052985 0.0052985" />
                            <joint name="ur16_wrist_2_joint" pos="0 0 0" axis="0 0 1" limited="true" range="-6.28319 6.28319" />
                            <geom pos="0 0 -0.12" type="mesh" rgba="0.7 0.7 0.7 1" mesh="ur16_wrist2" name="ur16_wrist2"/>
                            <body name="ur16_wrist_3_link" pos="0 0.11655 -2.39048e-11" quat="0.707107 -0.707107 0 0">
                                <inertial pos="0 0 -0.025" quat="0.5 0.5 -0.5 0.5" mass="0.907" diaginertia="0.000918337 0.000648127 0.000648127" />
                                <joint name="ur16_wrist_3_joint" pos="0 0 0" axis="0 0 1" limited="true" range="-6.28319 6.28319" />
                                <geom pos="0 0 -0.1168" quat="0.707107 0.707107 0 0" type="mesh" rgba="0.7 0.7 0.7 1" mesh="ur16_wrist3" name="ur16_wrist3"/>
                                <body name="ur16_peg" pos="0 0 0" quat="1 0 0 0">
                                    <geom pos="0.0 0 0.05"  size="0.01 0.05" type="cylinder" rgba="0.7 0.7 0.7 1" name="pegur160" />  
                                    <!-- <site name='force_sensor' pos="0 0 0.00" size='0.01 0.01 0.01' rgba='0 1 0 0' type='sphere' group='1'/>
                                    <site name='torque_sensor' pos="0 0 0.00" size='0.01 0.01 0.01' rgba='0 1 0 0' type='sphere' group='1'/>  
                                    <site name='acc' pos="0 0 0.0" size='0.01 0.01 0.01' rgba='0 1 0 0' type='sphere' group='1'/>                                                -->
                                    <site name='ur16:ee' pos="0 0.0 0.05" size='0.02 0.02 0.02' rgba='0 1 1 1' type='sphere' group='1'/>
                                </body>
                            </body>
                        </body>
                    </body>
                </body>
            </body>
        </body>        
    
        <geom condim="6" pos="0.15 0 -0.25" size="4.0 4.0 0.05" friction="1.0 0.005 0.0001" rgba="0 1 0 1" type="box"/>

    </worldbody>
</mujoco>
