<mujoco model="ur3e_robot">
    <compiler angle="radian" />
    <size njmax="500" nconmax="100" />
    <asset>
        <mesh name="base" file="base.stl" />
        <mesh name="shoulder" file="shoulder.stl" />
        <mesh name="upperarm" file="upperarm.stl" />
        <mesh name="forearm" file="forearm.stl" />
        <mesh name="wrist1" file="wrist1.stl" />
        <mesh name="wrist2" file="wrist2.stl" />
        <mesh name="wrist3" file="wrist3.stl" />
    </asset>
    <option 
        timestep="0.005" integrator="RK4">
    </option>
	<actuator>
		<motor gear="1.0" joint="shoulder_pan_joint" name="shoulder_pan_joint" ctrllimited="true" ctrlrange="-100 100"/>
		<motor gear="1.0" joint="shoulder_lift_joint" name="shoulder_lift_joint" ctrllimited="true" ctrlrange="-100 100"/>
		<motor gear="1.0" joint="elbow_joint" name="elbow_joint" ctrllimited="true" ctrlrange="-100 100"/>
		<motor gear="1.0" joint="wrist_1_joint" name="wrist_1_joint" ctrllimited="true" ctrlrange="-100 100"/>
        <motor gear="1.0" joint="wrist_2_joint" name="wrist_2_joint" ctrllimited="true" ctrlrange="-100 100"/>
        <motor gear="1.0" joint="wrist_3_joint" name="wrist_3_joint" ctrllimited="true" ctrlrange="-100 100"/>
        <!-- <motor gear="1.0" joint="joint:2" name="bact"/> -->
	</actuator>    
    <sensor>
        <force name='force_sensor' site='force_sensor'/>
        <torque name='torque_sensor' site='torque_sensor'/>
        <accelerometer name='acc' site='acc'/>
        <!-- <gyro name='gyro' site='gyro'/> -->
    </sensor>
    <worldbody>
    <!-- <camera name="bodyhigh2" pos="0 0 1.5" quat="0 0 0.382683 0 0.923876"/> -->
    <!-- <camera name="bodyhigh2" pos="0 0 1.5" quat="0 0.923876 0 0.382683"/> -->
        <geom quat="-1 0 0 0" type="mesh" rgba="0.7 0.7 0.7 1" mesh="base" />
        <body name="shoulder_link" pos="0 0 0.15285" quat="0 0 0 1">
            <inertial pos="0 0 0" mass="2" diaginertia="0.00809316 0.00809316 0.005625" />
            <joint name="shoulder_pan_joint" pos="0 0 0" axis="0 0 1" limited="true" range="-6.28319 6.28319" />
            <geom quat="0 0 0 1" type="mesh" rgba="0.7 0.7 0.7 1" mesh="shoulder" />
            <body name="upper_arm_link" pos="0 0 0" quat="0.707107 0.707107 0 0">
                <inertial pos="-0.121825 0 0.12" quat="0.707107 0 0.707107 0" mass="3.42" diaginertia="0.0217285 0.0217285 0.00961875" />
                <joint name="shoulder_lift_joint" pos="0 0 0" axis="0 0 1" limited="true" range="-6.28319 6.28319" />
                <!-- <joint name="shoulder_lift_joint" pos="0 0 0" axis="0 0 1" limited="true" range="-1.4544168120244623 -1.40" /> -->
                <geom pos="0 0 0.12" quat="0.5 0.5 -0.5 -0.5" type="mesh" rgba="0.7 0.7 0.7 1" mesh="upperarm" />
                <body name="forearm_link" pos="-0.24355 0 0">
                    <inertial pos="-0.1066 0 0.027" quat="0.707107 0 0.707107 0" mass="1.26" diaginertia="0.00654457 0.00654457 0.00354375" />
                    <joint name="elbow_joint" pos="0 0 0" axis="0 0 1" limited="true" range="-3.14159 3.14159" />
                    <!-- <joint name="elbow_joint" pos="0 0 0" axis="0 0 1" limited="true" range="-1.7540615253663132 -1.70" /> -->
                    <geom pos="0 0 0.027" quat="0.5 0.5 -0.5 -0.5" type="mesh" rgba="0.7 0.7 0.7 1" mesh="forearm" />
                    <body name="wrist_1_link" pos="-0.2132 0 0.13105">
                        <inertial pos="0 0 0" quat="0.5 0.5 -0.5 0.5" mass="0.8" diaginertia="0.00225 0.002085 0.002085" />
                        <joint name="wrist_1_joint" pos="0 0 0" axis="0 0 1" limited="true" range="-6.28319 6.28319" />
                        <!-- <joint name="wrist_1_joint" pos="0 0 0" axis="0 0 1" limited="true" range="-3.067826543422323 -2.9" /> -->
                        <geom pos="0 0 -0.104" quat="0.707107 0.707107 0 0" type="mesh" rgba="0.7 0.7 0.7 1" mesh="wrist1" />
                        <body name="wrist_2_link" pos="0 -0.08535 -1.75056e-11" quat="0.707107 0.707107 0 0">
                            <inertial pos="0 0 0" quat="0.5 0.5 -0.5 0.5" mass="0.8" diaginertia="0.00225 0.002085 0.002085" />
                            <joint name="wrist_2_joint" pos="0 0 0" axis="0 0 1" limited="true" range="-6.28319 6.28319"/>
                            <!-- <joint name="wrist_2_joint" pos="0 0 0" axis="0 0 1" limited="true" range="0.10 0.11940037001951656" />  -->
                            <geom pos="0 0 -0.08535" type="mesh" rgba="0.7 0.7 0.7 1" mesh="wrist2" name="wrist2"/>
                            <body name="wrist_3_link" pos="0 0.0921 -1.889e-11" quat="0.707107 -0.707107 0 0">
                                <inertial pos="0 0 -0.02" quat="0.5 0.5 -0.5 0.5" mass="0.35" diaginertia="0.0001792 0.000136267 0.000136267" />
                                <!-- <joint name="wrist_3_joint" pos="0 0 0" axis="0 0 1" limited="true" range="-1.588058798181077 -1.57" /> -->
                                <joint name="wrist_3_joint" pos="0 0 0" axis="0 0 1" limited="true" range="-6.28319 6.28319" />
                                <geom pos="0 0 -0.0921" quat="0.707107 0.707107 0 0" type="mesh" rgba="0.7 0.7 0.7 1" mesh="wrist3" name="wrist3" />
                                
                                <body name="peg_base" pos="0 0 0.0025" >
                                    <geom pos="0.0 0 0.0"  size="0.03 0.0025" type="cylinder" rgba="0.7 0.7 0.7 1" name="pegbase" />
                                    <body name="peg" pos="0 0 0.0" >
                                        <geom pos="0.0 0 0.0025"  size="0.03 0.0025" type="cylinder" rgba="0.7 0.7 0.7 1" name="peg0" />   
                                        <!-- <geom pos="0.03 0 0.01"  size="0.01 0.01" type="cylinder" rgba="0.7 0.7 0.7 1" name="peg0" />
                                        <geom pos="-0.03 0 0.01"  size="0.01 0.01" type="cylinder" rgba="0.7 0.7 0.7 1" name="peg1"/> -->
                                        <!-- <site name='acc' pos="0 0 0.0" size='0.01 0.01 0.01' rgba='0 1 0 1' type='sphere' group='1'/>
                                        <site name='gyro' pos="0 0 0.0" size='0.01 0.01 0.01' rgba='0 1 0 1' type='sphere' group='1'/> -->
                                        <inertial pos = "0. 0. 0." mass="0.002"/>
                                        <!-- <body name="pegtip" pos="0 0 0.060" > -->
                                        <site name='force_sensor' pos="0 0 0.00" size='0.01 0.01 0.01' rgba='0 1 0 0' type='sphere' group='1'/>
                                        <site name='torque_sensor' pos="0 0 0.00" size='0.01 0.01 0.01' rgba='0 1 0 0' type='sphere' group='1'/>
                                        <site name='mep:ee' pos="0 0.0 -0.05" size='0.01 0.01 0.01' rgba='0 1 1 1' type='sphere' group='1'/>
                                        <site name='acc' pos="0 0 0.0" size='0.01 0.01 0.01' rgba='0 1 0 0' type='sphere' group='1'/>
                                    </body>
                                </body>                                
                            </body>
                        </body>
                    </body>
                </body>
            </body>
        </body>
        
        <!-- <site name='wpt1' pos="0.02526912 0.44041631 0.3" size='0.015 0.015 0.015' rgba='0 0 1 1' type='sphere' group='1' quat="-0.65328148 0.27059805007309845 0.6532814824381883 0.27059805007309845"/>  -->
        <!-- <site name='wpt2' pos="0.26 0.2 0.3" size='0.0015 0.0015 0.0015' rgba='0 0 1 1' type='sphere' group='1'/> -->
        <!-- <body name="nozzle" pos="0.261 0.2 0.3" quat="1 0 0 0"> -->
        <body name="wall" pos="-0.3 0.25 0"  quat="0.9238795325112867 0 0 -0.3826834323650898">
            <geom pos="0.0 0 0.0"  size="0.05 1 1" type="box" rgba="0.7 0.7 0.7 1" name="wallg" />
            <site name='wpt1' pos="0.05 0.4 0.3" size='0.015 0.015 0.015' rgba='0 0 1 1' type='sphere' group='1' quat="0.707107 0 -0.707107 0"/>
        </body>   
        <!-- <body name="floor" pos="0.15 0 -0.6"> -->
        <geom condim="6" pos="0.15 0 -0.25" size="4.0 4.0 0.05" friction="1.0 0.005 0.0001" rgba="0 1 0 1" type="box"/>
        
            <!-- <site name="target" pos="0.3 0.2 0.3" size=".1 .1 .1" rgba="0 0 1 1" type="sphere"/> -->
        <!-- </body> -->
    </worldbody>
</mujoco>
